<?xml version="1.0" encoding="utf-8"?>
<!-- =================================================================================== -->
<!-- |    This document was autogenerated by xacro from lara3.urdf.xacro               | -->
<!-- |    EDITING THIS FILE BY HAND IS NOT RECOMMENDED                                 | -->
<!-- =================================================================================== -->
<robot name="maira" xmlns:controller="http://playerstage.sourceforge.net/gazebo/xmlschema/#controller" xmlns:interface="http://playerstage.sourceforge.net/gazebo/xmlschema/#interface" xmlns:sensor="http://playerstage.sourceforge.net/gazebo/xmlschema/#sensor">
  <!-- values not comfirmed. 12/05/2022 heitmann-->
  <!-- values from chinese urdf, not sure if good but best we have. 17/05/22 temminghoff-->
  <!-- values not comfirmed. 12/05/2022 heitmann-->
  <material name="white">
    <color rgba="1 1 1 1"/>
  </material>
  <!-- ============================ BASE ================================= -->
  <link name="lara3_root_link">
  </link>
  <joint name="lara3_root_joint" type="fixed">
    <origin rpy="0 -1.57079632679 0" xyz="0 0 0"/>
    <axis xyz="0 0 1"/>
    <parent link="lara3_root_link"/>
    <child link="lara3_link0"/>
  </joint>
  <link name="lara3_link0">
    <inertial>
      <mass value="1.336"/>
      <origin rpy="0 0 0" xyz="0.0 0.0 0.0"/>
      <inertia ixx="0.0" ixy="0.0" ixz="0.0" iyy="0.0" iyz="0.0" izz="0.0"/>
    </inertial>
    <visual>
      <origin rpy="0 0 0" xyz="0 0 0"/>
      <geometry>
        <mesh filename="meshes/Link0_body.stl"/>
      </geometry>
      <material name="white"/>
    </visual>
    <visual>
      <origin rpy="0 0 0" xyz="0 0 0"/>
      <geometry>
        <mesh filename="meshes/Link0_connector.stl"/>
      </geometry>
      <material name="white"/>
    </visual>
    <collision>
      <origin rpy="0 0 0" xyz="0 0 0"/>
      <geometry>
        <mesh filename="collision/Link0_body.stl"/>
      </geometry>
      <material name="white"/>
    </collision>
  </link>
  <!-- ============================ DOF1 ================================= -->
  <joint name="lara3_joint1" type="revolute">
    <origin rpy="0 0 1.5708" xyz="0.1925 0 0"/>
    <axis xyz="0 -1 0"/>
    <limit effort="204" lower="-3.1415926" upper="3.1415926" velocity="3.14159"/>
    <parent link="lara3_link0"/>
    <child link="lara3_link1"/>
  </joint>
  <link name="lara3_link1">
    <inertial>
      <mass value="4.696"/>
      <origin rpy="0 0 0" xyz="0.02107 0.047171 -1.8203e-05"/>
      <inertia ixx="0.01618588349" ixy="-4.944e-07" ixz="0.0037881237" iyy="0.0199814541" iyz="-1.9776e-06" izz="0.0097480539"/>
    </inertial>
    <visual>
      <origin rpy="0 0 0" xyz="0 0 0"/>
      <geometry>
        <mesh filename="meshes/Link1_body.stl"/>
      </geometry>
      <material name="white"/>
    </visual>
    <visual>
      <origin rpy="0 0 0" xyz="0 0 0"/>
      <geometry>
        <mesh filename="meshes/Link1_rings.stl"/>
      </geometry>
      <material name="white"/>
    </visual>
    <collision>
      <origin rpy="0 0 0" xyz="0 0 0"/>
      <geometry>
        <mesh filename="collision/Link1_body.stl"/>
      </geometry>
      <material name="white"/>
    </collision>
  </link>
  <!-- ============================ DOF2 ================================= -->
  <joint name="lara3_joint2" type="revolute">
    <origin rpy="0 0 0" xyz="0 0 0"/>
    <axis xyz="1 0 0"/>
    <limit effort="204" lower="-3.1415926" upper="3.1415926" velocity="2.3492"/>
    <!--<safety_controller k_position="100" k_velocity="2" soft_lower_limit="-2.105948851735" soft_upper_limit="2.105948851735" />-->
    <!-- <dynamics damping="13.0" friction="9.0" /> -->
    <parent link="lara3_link1"/>
    <child link="lara3_link2"/>
  </joint>
  <link name="lara3_link2">
    <inertial>
      <mass value="1.605"/>
      <origin rpy="0 0 0" xyz="0.1086659 -0.12227 -2.0075e-05"/>
      <inertia ixx="0.01685959619" ixy="-3.9861e-06" ixz="0.0" iyy="0.0016560546" iyz="0.0008180157" izz="0.0174527217"/>
    </inertial>
    <visual>
      <origin rpy="0 0 0" xyz="0 0 0"/>
      <geometry>
        <mesh filename="meshes/Link2_body.stl"/>
      </geometry>
      <material name="white"/>
    </visual>
    <collision>
      <origin rpy="0 0 0" xyz="0 0 0"/>
      <geometry>
        <mesh filename="collision/Link2_body.stl"/>
      </geometry>
      <material name="white"/>
    </collision>
  </link>
  <!-- ============================ DOF3 ================================= -->
  <joint name="lara3_joint3" type="revolute">
    <origin rpy="0 0 0" xyz="0 -0.266 0"/>
    <axis xyz="1 0 0"/>
    <limit effort="107" lower="-2.6179938" upper="2.6179938" velocity="2.6093"/>
    <parent link="lara3_link2"/>
    <child link="lara3_link3"/>
  </joint>
  <link name="lara3_link3">
    <inertial>
      <mass value="3.322"/>
      <origin rpy="0 0 0" xyz="0.0208349 -0.041461 9.6224e-06"/>
      <inertia ixx="0.0115212195" ixy="1.1433e-06" ixz="2.2557e-06" iyy="0.0056319267" iyz="0.0022254489" izz="0.0091655271"/>
    </inertial>
    <visual>
      <origin rpy="0 0 0" xyz="0 0 0"/>
      <geometry>
        <mesh filename="meshes/Link3_body.stl"/>
      </geometry>
      <material name="white"/>
    </visual>
    <visual>
      <origin rpy="0 0 0" xyz="0 0 0"/>
      <geometry>
        <mesh filename="meshes/Link3_rings.stl"/>
      </geometry>
      <material name="white"/>
    </visual>
    <collision>
      <origin rpy="0 0 0" xyz="0 0 0"/>
      <geometry>
        <mesh filename="collision/Link3_body.stl"/>
      </geometry>
      <material name="white"/>
    </collision>
  </link>
  <!-- ============================ DOF4 ================================= -->
  <joint name="lara3_joint4" type="revolute">
    <origin rpy="0 0 0" xyz="0 0 0"/>
    <axis xyz="0 -1 0"/>
    <limit effort="107" lower="-3.1415926" upper="3.1415926" velocity="3.14159"/>
    <!--<safety_controller k_position="100" k_velocity="2" soft_lower_limit="-2.55948851735" soft_upper_limit="2.55948851735" />-->
    <!-- <dynamics damping="2.5" friction="4.0" /> -->
    <parent link="lara3_link3"/>
    <child link="lara3_link4"/>
  </joint>
  <link name="lara3_link4">
    <inertial>
      <mass value="1.144"/>
      <origin rpy="0 0 0" xyz="0.0553179 -0.20367309 -3.0677e-06"/>
      <inertia ixx="0.0073628211" ixy="3.399e-07" ixz="0.002563" iyy="0.0088114749" iyz="-9.888e-07" izz="0.00295892219"/>
    </inertial>
    <visual>
      <origin rpy="0 0 0" xyz="0 0 0"/>
      <geometry>
        <mesh filename="meshes/Link4_body.stl"/>
      </geometry>
      <material name="white"/>
    </visual>
    <collision>
      <origin rpy="0 0 0" xyz="0 0 0"/>
      <geometry>
        <mesh filename="collision/Link4_body.stl"/>
      </geometry>
      <material name="white"/>
    </collision>
  </link>
  <!-- ============================ DOF5 ================================= -->
  <joint name="lara3_joint5" type="revolute">
    <origin rpy="0 0 0" xyz="0 -0.324 0"/>
    <axis xyz="1 0 0"/>
    <limit effort="36" lower="-2.4434609" upper="2.4434609" velocity="2.5587"/>
    <!--<safety_controller k_position="100" k_velocity="2" soft_lower_limit="-2.55948851735" soft_upper_limit="2.55948851735" />-->
    <!-- <dynamics damping="5.0" friction="4.0" /> -->
    <parent link="lara3_link4"/>
    <child link="lara3_link5"/>
  </joint>
  <link name="lara3_link5">
    <inertial>
      <mass value="2.494"/>
      <origin rpy="0 0 0" xyz="0.01661199 -0.038279 3.7144e-06"/>
      <inertia ixx="0.0075907395" ixy="3.399e-07" ixz="6.18e-08" iyy="0.00348728129" iyz="0.0014567805" izz="0.005985917"/>
    </inertial>
    <visual>
      <origin rpy="0 0 0" xyz="0 0 0"/>
      <geometry>
        <mesh filename="meshes/Link5_body.stl"/>
      </geometry>
      <material name="white"/>
    </visual>
    <visual>
      <origin rpy="0 0 0" xyz="0 0 0"/>
      <geometry>
        <mesh filename="meshes/Link5_rings.stl"/>
      </geometry>
      <material name="white"/>
    </visual>
    <collision>
      <origin rpy="0 0 0" xyz="0 0 0"/>
      <geometry>
        <mesh filename="collision/Link5_body.stl"/>
      </geometry>
      <material name="white"/>
    </collision>
  </link>
  <!-- ============================ DOF6 ================================= -->
  <joint name="lara3_joint6" type="revolute">
    <origin rpy="0 3.14159 0" xyz="0 0 0"/>
    <axis xyz="0 -1 0"/>
    <limit effort="36" lower="-6.283185307" upper="6.283185307" velocity="3.14159"/>
    <!--<safety_controller k_position="100" k_velocity="2" soft_lower_limit="-4.0" soft_upper_limit="4.0" />-->
    <!-- <dynamics damping="1.25" friction="1.25" /> -->
    <parent link="lara3_link5"/>
    <child link="lara3_link6"/>
  </joint>
  <link name="lara3_link6">
    <inertial>
      <mass value="0.455"/>
      <origin rpy="0 0 0" xyz="0.00708959 -0.13460309 0.00016176"/>
      <inertia ixx="0.000599676299" ixy="-8.9301e-06" ixz="4.326e-06" iyy="0.00060242639" iyz="1.545e-07" izz="0.0006053928"/>
    </inertial>
    <visual>
      <origin rpy="0 0 0" xyz="0 0 0"/>
      <geometry>
        <mesh filename="meshes/Link6_body.stl"/>
      </geometry>
      <material name="white"/>
    </visual>
    <visual>
      <origin rpy="0 0 0" xyz="0 0 0"/>
      <geometry>
        <mesh filename="meshes/Link6_connector.stl"/>
      </geometry>
      <material name="white"/>
    </visual>
    <collision>
      <origin rpy="0 0 0" xyz="0 0 0"/>
      <geometry>
        <mesh filename="collision/Link6_body.stl"/>
      </geometry>
      <material name="white"/>
    </collision>
  </link>
  <!-- ============================ Flange ================================= -->
  <link name="lara3_flange"/>
  <joint name="lara3_link6_to_flange" type="fixed">
    <origin rpy="1.57079632679 1.57079632679 0" xyz="0 -0.1655 0"/>
    <parent link="lara3_link6"/>
    <child link="lara3_flange"/>
  </joint>
  <link name="world"/>
  <joint name="world_joint" type="fixed">
    <parent link="world"/>
    <child link="lara3_root_link"/>
    <origin rpy="0.0 0.0 0.0" xyz="0.0 0.0 0.0"/>
  </joint>
</robot>

