<?xml version="1.0" encoding="utf-8"?>
<!-- =================================================================================== -->
<!-- |    This document was autogenerated by xacro from lara8.urdf.xacro               | -->
<!-- |    EDITING THIS FILE BY HAND IS NOT RECOMMENDED                                 | -->
<!-- =================================================================================== -->
<robot name="maira" xmlns:controller="http://playerstage.sourceforge.net/gazebo/xmlschema/#controller" xmlns:interface="http://playerstage.sourceforge.net/gazebo/xmlschema/#interface" xmlns:sensor="http://playerstage.sourceforge.net/gazebo/xmlschema/#sensor">
  <!-- values not correct. 12/05/2022 heitmann-->
  <!-- values not correct. 12/05/2022 heitmann-->
  <material name="white">
    <color rgba="1 1 1 1"/>
  </material>
  <!-- values not correct. 12/05/2022 heitmann-->
  <!-- ============================ BASE ================================= -->
  <link name="lara8_root_link">
  </link>
  <joint name="lara8_root_joint" type="fixed">
    <origin rpy="0 -1.57079632679 0" xyz="0 0 0"/>
    <axis xyz="0 0 1"/>
    <parent link="lara8_root_link"/>
    <child link="lara8_link0"/>
  </joint>
  <link name="lara8_link0">
    <inertial>
      <mass value="2.13370989"/>
      <origin rpy="0 0 0" xyz="0.0 0.0 0.0"/>
      <inertia ixx="0.0" ixy="0.0" ixz="0.0" iyy="0.0" iyz="0.0" izz="0.0"/>
    </inertial>
    <visual>
      <origin rpy="0 0 0" xyz="0 0 0"/>
      <geometry>
        <mesh filename="meshes/Link0_body.stl"/>
      </geometry>
      <material name="white"/>
    </visual>
    <visual>
      <origin rpy="0 0 0" xyz="0 0 0"/>
      <geometry>
        <mesh filename="meshes/Link0_connector.stl"/>
      </geometry>
      <material name="white"/>
    </visual>
    <collision>
      <origin rpy="0 0 0" xyz="0 0 0"/>
      <geometry>
        <mesh filename="collision/Link0_body.stl"/>
      </geometry>
      <material name="white"/>
    </collision>
  </link>
  <!-- ============================ DOF1 ================================= -->
  <joint name="lara8_joint1" type="revolute">
    <origin rpy="0 0 1.5708" xyz="0.26 0 0"/>
    <axis xyz="0 -1 0"/>
    <limit effort="204" lower="-3.1415926" upper="3.1415926" velocity="3.14159"/>
    <parent link="lara8_link0"/>
    <child link="lara8_link1"/>
  </joint>
  <link name="lara8_link1">
    <inertial>
      <mass value="7.962"/>
      <origin rpy="0 0 0" xyz="-0.021749 0.051099 -1.2e-05"/>
      <inertia ixx="0.040138" ixy="-0.008898" ixz="3e-06" iyy="0.022282" iyz="-2e-06" izz="0.047361"/>
    </inertial>
    <visual>
      <origin rpy="0 0 0" xyz="0 0 0"/>
      <geometry>
        <mesh filename="meshes/Link1_body.stl"/>
      </geometry>
      <material name="white"/>
    </visual>
    <visual>
      <origin rpy="0 0 0" xyz="0 0 0"/>
      <geometry>
        <mesh filename="meshes/Link1_rings.stl"/>
      </geometry>
      <material name="white"/>
    </visual>
    <collision>
      <origin rpy="0 0 0" xyz="0 0 0"/>
      <geometry>
        <mesh filename="collision/Link1_body.stl"/>
      </geometry>
      <material name="white"/>
    </collision>
  </link>
  <!-- ============================ DOF2 ================================= -->
  <joint name="lara8_joint2" type="revolute">
    <origin rpy="0 0 0" xyz="0 0 0"/>
    <axis xyz="1 0 0"/>
    <limit effort="204" lower="-3.1415926" upper="3.1415926" velocity="2.3492"/>
    <parent link="lara8_link1"/>
    <child link="lara8_link2"/>
  </joint>
  <link name="lara8_link2">
    <inertial>
      <mass value="3.735"/>
      <origin rpy="0 0 0" xyz="-0.130318 -0.15801 0.0"/>
      <inertia ixx="0.091957" ixy="0.003907" ixz="1e-06" iyy="0.005196" iyz="-6e-06" izz="0.090991"/>
    </inertial>
    <visual>
      <origin rpy="0 0 0" xyz="0 0 0"/>
      <geometry>
        <mesh filename="meshes/Link2_body.stl"/>
      </geometry>
      <material name="white"/>
    </visual>
    <collision>
      <origin rpy="0 0 0" xyz="0 0 0"/>
      <geometry>
        <mesh filename="collision/Link2_body.stl"/>
      </geometry>
      <material name="white"/>
    </collision>
  </link>
  <!-- ============================ DOF3 ================================= -->
  <joint name="lara8_joint3" type="revolute">
    <origin rpy="0 0 0" xyz="0 -0.6 0"/>
    <axis xyz="1 0 0"/>
    <limit effort="107" lower="-2.6179938" upper="2.6179938" velocity="2.6093"/>
    <parent link="lara8_link2"/>
    <child link="lara8_link3"/>
  </joint>
  <link name="lara8_link3">
    <inertial>
      <mass value="4.715"/>
      <origin rpy="0 0 0" xyz="-0.01936 -0.041461 -2.1e-05"/>
      <inertia ixx="0.01631" ixy="0.003836" ixz="-1e-06" iyy="0.009822" iyz="-2e-06" izz="0.020163"/>
    </inertial>
    <visual>
      <origin rpy="0 0 0" xyz="0 0 0"/>
      <geometry>
        <mesh filename="meshes/Link3_body.stl"/>
      </geometry>
      <material name="white"/>
    </visual>
    <visual>
      <origin rpy="0 0 0" xyz="0 0 0"/>
      <geometry>
        <mesh filename="meshes/Link3_rings.stl"/>
      </geometry>
      <material name="white"/>
    </visual>
    <collision>
      <origin rpy="0 0 0" xyz="0 0 0"/>
      <geometry>
        <mesh filename="collision/Link3_body.stl"/>
      </geometry>
      <material name="white"/>
    </collision>
  </link>
  <!-- ============================ DOF4 ================================= -->
  <joint name="lara8_joint4" type="revolute">
    <origin rpy="0 0 0" xyz="0 0 0"/>
    <axis xyz="0 -1 0"/>
    <limit effort="107" lower="-3.1415926" upper="3.1415926" velocity="3.14159"/>
    <parent link="lara8_link3"/>
    <child link="lara8_link4"/>
  </joint>
  <link name="lara8_link4">
    <inertial>
      <mass value="1.468"/>
      <origin rpy="0 0 0" xyz="-0.058796 -0.257035 4.8e-05"/>
      <inertia ixx="0.016761" ixy="-0.004792" ixz="2e-06" iyy="0.004072" iyz="6e-06" izz="0.018771"/>
    </inertial>
    <visual>
      <origin rpy="0 0 0" xyz="0 0 0"/>
      <geometry>
        <mesh filename="meshes/Link4_body.stl"/>
      </geometry>
      <material name="white"/>
    </visual>
    <collision>
      <origin rpy="0 0 0" xyz="0 0 0"/>
      <geometry>
        <mesh filename="collision/Link4_body.stl"/>
      </geometry>
      <material name="white"/>
    </collision>
  </link>
  <!-- ============================ DOF5 ================================= -->
  <joint name="lara8_joint5" type="revolute">
    <origin rpy="0 0 0" xyz="0 -0.7 0"/>
    <axis xyz="1 0 0"/>
    <limit effort="36" lower="-3.1415926" upper="3.1415926" velocity="3.14159"/>
    <parent link="lara8_link4"/>
    <child link="lara8_link5"/>
  </joint>
  <link name="lara8_link5">
    <inertial>
      <mass value="2.498"/>
      <origin rpy="0 0 0" xyz="-0.015915 -0.036566 0.0"/>
      <inertia ixx="0.006007" ixy="0.001465" ixz="0.0" iyy="0.003499" iyz="0.0" izz="0.007622"/>
    </inertial>
    <visual>
      <origin rpy="0 0 0" xyz="0 0 0"/>
      <geometry>
        <mesh filename="meshes/Link5_body.stl"/>
      </geometry>
      <material name="white"/>
    </visual>
    <visual>
      <origin rpy="0 0 0" xyz="0 0 0"/>
      <geometry>
        <mesh filename="meshes/Link5_rings.stl"/>
      </geometry>
      <material name="white"/>
    </visual>
    <collision>
      <origin rpy="0 0 0" xyz="0 0 0"/>
      <geometry>
        <mesh filename="collision/Link5_body.stl"/>
      </geometry>
      <material name="white"/>
    </collision>
  </link>
  <!-- ============================ DOF6 ================================= -->
  <joint name="lara8_joint6" type="revolute">
    <origin rpy="0 3.14159 0" xyz="0 0 0"/>
    <axis xyz="0 -1 0"/>
    <limit effort="36" lower="-6.283185307" upper="6.283185307" velocity="3.14159"/>
    <parent link="lara8_link5"/>
    <child link="lara8_link6"/>
  </joint>
  <link name="lara8_link6">
    <inertial>
      <mass value="0.455"/>
      <origin rpy="0 0 0" xyz="-0.000924 -0.149191 -0.000337"/>
      <inertia ixx="0.0006" ixy="4e-06" ixz="-9e-06" iyy="0.000605" iyz="0.0" izz="0.000602"/>
    </inertial>
    <visual>
      <origin rpy="0 0 0" xyz="0 0 0"/>
      <geometry>
        <mesh filename="meshes/Link6_body.stl"/>
      </geometry>
      <material name="white"/>
    </visual>
    <collision>
      <origin rpy="0 0 0" xyz="0 0 0"/>
      <geometry>
        <mesh filename="collision/Link6_body.stl"/>
      </geometry>
      <material name="white"/>
    </collision>
  </link>
  <!-- ============================ Flange ================================= -->
  <link name="lara8_flange"/>
  <joint name="lara8_link6_to_flange" type="fixed">
    <origin rpy="1.57079632679 1.57079632679 0" xyz="0 -0.1735 0"/>
    <parent link="lara8_link6"/>
    <child link="lara8_flange"/>
  </joint>
  <link name="world"/>
  <joint name="world_joint" type="fixed">
    <parent link="world"/>
    <child link="lara8_root_link"/>
    <origin rpy="0.0 0.0 0.0" xyz="0.0 0.0 0.0"/>
  </joint>
</robot>

